Workbook

Sheet Dashboard
A1: Tata Power — Double Materiality Assessment
A2: Executive ESG Dashboard | Impact & Financial Materiality | FY2025–26
A4: ESG TOPICS ASSESSED | D4: DOUBLE MATERIAL | G4: IMPACT MATERIAL | J4: FINANCIALLY MATERIAL | M4: BELOW THRESHOLD
A5: =COUNTA('DMA Matrix'!A5:A34) -> 30 | D5: =COUNTIF('DMA Matrix'!H5:H34,"Double Material") -> 22 | G5: =COUNTIF('DMA Matrix'!H5:H34,"Impact Material") -> 7 | J5: =COUNTIF('DMA Matrix'!H5:H34,"Financially Material") -> 1 | M5: =COUNTIF('DMA Matrix'!H5:H34,"Below Threshold") -> 0
J9: Materiality by ESG Category
J10: Environmental | K10: =COUNTIFS('DMA Matrix'!B5:B34,"Environmental",'DMA Matrix'!H5:H34,"Double Material") -> 6
J11: Social | K11: =COUNTIFS('DMA Matrix'!B5:B34,"Social",'DMA Matrix'!H5:H34,"Double Material") -> 7
J12: Governance | K12: =COUNTIFS('DMA Matrix'!B5:B34,"Governance",'DMA Matrix'!H5:H34,"Double Material") -> 9
A27: Key Takeaways | J27: Key Strategic ESG Themes
A28: ="01 | Broad ESG Materiality — "&IF(M5=0,"All "&A5&" assessed ESG topics",(A5-M5)&" of "&A5&" assessed ESG topics")&" cross at least one materiality threshold." -> 01 | Broad ESG Materiality — All 30 assessed ESG topics cross at least one materiality threshold. | J28: 01 | Climate & Decarbonisation -Climate Change • GHG Emissions • Energy Management • Clean Technology
A29: ="02 | Strong Double Materiality — "&D5&" of "&A5&" topics ("&TEXT(D5/A5,"0.0%")&") are material from both impact and financial perspectives." -> 02 | Strong Double Materiality — 22 of 30 topics (73.3%) are material from both impact and financial perspectives. | J29: 02 | Environmental & Resource Stewardship -Air Pollution • Water • Waste • Ash • Biodiversity • Resource Efficiency
A30: ="03 | Governance Concentration — "&K12&" of "&COUNTIF('DMA Matrix'!B5:B34,"Governance")&" governance topics are classified as Double Material." -> 03 | Governance Concentration — 9 of 10 governance topics are classified as Double Material. | J30: 03 | Safe, Reliable & Affordable Energy- OHS • Energy Reliability • Access & Affordability • Customer Protection
A31: ="04 | Benchmarked — Alignment Index "&TEXT(Benchmark!C21,"0%")&" and top-band recall "&TEXT(Benchmark!C22,"0%")&" against Tata Power's official FY26 DMA (Grade "&Benchmark!C24&")." -> 04 | Benchmarked — Alignment Index 85% and top-band recall 60% against Tata Power's official FY26 DMA (Grade B: Moderate). | J31: 04 | People, Communities & Responsible Value Chain - Human Rights • Labour Practices • Community Impact • D&I • Supply Chain
J32: 05 | Governance, Digital & ESG Risk Resilience - Regulatory Compliance • ESG Governance • ESG Risk • Cybersecurity • Data Privacy
A33: Assessment Scope
A34: Sr. No | B34: Parameter | E34: Details
A35: 1 | B35: Company | E35: Tata Power Company Limited
A36: 2 | B36: Assessment Period | E36: FY2025–26
A37: 3 | B37: ESG Topics | E37: =A5 -> 30
A38: 4 | B38: Assessment Dimensions | E38: Impact + Financial Materiality
A39: 5 | B39: Evidence Base | E39: Publicly available information
A40: 6 | B40: Assessment Type | E40: Independent analytical assessment
A41: 7 | B41: Benchmark & sync | E41: ="Alignment "&TEXT(Benchmark!C21,"0%")&" | Grade "&LEFT(Benchmark!C24,1)&" | Workbook sync: " -> Alignment 85% | Grade B | Workbook sync:
A42: Disclaimer: This is an independent analytical assessment based on publicly available information and does not represent Tata Power's official DMA.

Sheet Company Context
A1: Tata Power — Integrated Energy Platform Navigating India's Energy Transition
A2: Business scale, clean-energy expansion and increasing ESG complexity shape the materiality landscape
A4: Tata Power at a Glance | FY2025 - 26
A5: 16,716 MW | B5: 7,856 MW | C5: 13.1+ Mn | G5: ₹63,681 Cr | J5: ₹16,090 Cr
A6: Generation Portfolio | B6: Clean & Green Operational Capacity | C6: Distribution Customers | G6: Revenue | J6: EBITDA
A9: Clean & green capacity represented ~47% of Tata Power’s operational portfolio in FY26.
A12: Why Materiality Matters for Tata Power | D12: Integrated Energy Value Chain
D13: GENERATION → TRANSMISSION → DISTRIBUTION → RENEWABLES → ENERGY SOLUTIONS
A14: 01 | Energy Transition
A15: Decarbonisation • GHG emissions • Energy efficiency • Clean technology | D15: Generation | F15: Thermal • Hydro • Solar • Wind • Waste Heat Recovery
A16: 02 | Environmental Footprint | D16: Transmission | F16: 7,403 ckm transmission portfolio
A17: Water • Air pollution • Ash • Waste • Biodiversity • Land use | D17: Distribution | F17: 13.1+ million customers across India
A18: 03 | Stakeholder Dependence | D18: Renewables | F18: Solar • Wind • Hydro • Rooftop Solar • Storage
A19: Employees • Contractors • Customers • Communities • Suppliers | D19: Energy Solutions | F19: EV Charging • Rooftop Solar • Microgrids • Digital Energy Solutions
A20: 04 | Infrastructure & Digital Resilience
A21: Energy reliability • Cybersecurity • Data privacy • Supply-chain resilience | D21: Tata Power operates across the power value chain, combining conventional generation with expanding clean-energy and customer-facing businesses
A25: Strategic Context
A26: Tata Power’s integrated business model creates a dual ESG challenge: scaling clean, reliable and affordable energy while managing the environmental, social and governance impacts of a large infrastructure-intensive power business.
A29: DMA Implication:
A30: The assessment therefore considers both Tata Power’s impacts on people and the environment and the financial implications of ESG-related risks and opportunities.
A32: Source: Tata Power Integrated Annual Report FY2025–26 and corporate disclosures. FY2025–26 figures unless otherwise stated
A33: Independent analytical assessment based on publicly available information; not Tata Power’s official DMA.

Sheet ESG Issue Universe
A1: Tata Power - ESG Issue Universe
A3: Issue Id | B3: ESG Category | C3: ESG Topic | D3: Sub Topic | E3: Why Relevant to Tata Power | F3: Value Chain Stage
A4: E01 | B4: Environmental | C4: Climate Change | D4: Climate transition | E4: Tata Power is transitioning its portfolio toward clean energy while managing the long-term transition of conventional generation. | F4: Generation | Renewables | Transmission & Distribution
A5: E02 | B5: Environmental | C5: GHG Emissions | D5: Scope 1, 2 & 3 | E5: Power generation is emissions-intensive; Tata Power therefore needs to reduce operational emissions and manage value-chain emissions. | F5: Generation | Supply Chain | T&D
A6: E03 | B6: Environmental | C6: Energy Management | D6: Energy efficiency | E6: Energy efficiency across generation, transmission and distribution can reduce resource consumption, losses and operating costs. | F6: Generation | T&D | Energy Solutions
A7: E04 | B7: Environmental | C7: Air Pollution | D7: SOx, NOx, PM | E7: Thermal generation can create air-emission impacts, making emission-control systems and regulatory compliance important. | F7: Thermal Generation | Supply Chain
A8: E05 | B8: Environmental | C8: Water | D8: Water withdrawal & consumption | E8: Power generation requires significant water resources, making water efficiency and conservation important for operational resilience. | F8: Thermal & Hydro Generation | Communities
A9: E06 | B9: Environmental | C9: Biodiversity | D9: Ecosystem impact | E9: Large-scale generation, transmission and renewable projects can interact with ecosystems and biodiversity-sensitive areas. | F9: Generation | Transmission | Renewables
A10: E07 | B10: Environmental | C10: Waste Management | D10: Waste & recycling | E10: Diverse operations generate hazardous, non-hazardous and industrial waste requiring responsible treatment and disposal. | F10: Generation | Manufacturing | Projects
A11: E08 | B11: Environmental | C11: Ash Management | D11: Fly ash / bottom ash | E11: Thermal operations generate substantial ash, requiring utilisation, safe handling, storage and regulatory compliance. | F11: Thermal Generation | Supply Chain
A12: E09 | B12: Environmental | C12: Land Use | D12: Land footprint | E12: Utility-scale generation, transmission and renewable projects require significant land and can affect local ecosystems and communities. | F12: Generation | Transmission | Renewables
A13: E10 | B13: Environmental | C13: Resource Use & Circular Economy | D13: Materials & circularity | E13: Large infrastructure projects require metals, equipment and other resources, creating opportunities for resource efficiency and circularity. | F13: Projects | Manufacturing | Generation
A14: S01 | B14: Social | C14: Occupational Health & Safety | D14: Workplace safety | E14: Power generation, construction, transmission and distribution involve high-risk activities requiring strong safety management. | F14: Generation | Transmission | Distribution | Projects
... A33: G10 | B33: Governance | C33: Creating Economic Value | D33: Sustainable growth | E33: Tata Power must balance investment in energy transition and infrastructure with profitability, financial resilience and long-term value creation. | F33: All Operations | Corporate

Sheet Evidence Database
A1: Tata Power — ESG Evidence Database
A2: Publicly Disclosed Evidence Supporting Materiality Assessment | FY2025–26
A4: Issue Id | B4: ESG Topic | C4: Evidence /Observation | D4: Impact Relevance | E4: Financial Relevance | F4: Risk/ Opportunity | G4: Tata Power Response | H4: Source Document | I4: Page | J4: Source Type | K4: Evidence Strength | L4: Official FY26 topic & band
A5: E01 | B5: Climate Change | C5: Tata Power identifies continued exposure to thermal assets as a source of carbon-pricing and stranded-asset risk. The company also identifies renewable-energy expansion as an opportunity and targets Net Zero emissions by 2045. | D5: Thermal generation contributes to GHG emissions and climate impacts; transition toward renewable energy can reduce lifecycle emissions. | E5: Carbon pricing, transition costs, stranded assets and changing energy-market expectations can affect long-term competitiveness and capital allocation. | F5: Risk + Opportunity | G5: Project Aalingana, SBTi-aligned targets, renewable expansion and transition toward cleaner energy; Net Zero target before 2045. | H5: TATA POWER FY 2025-26 BRSR | I5: 293 | J5: Company Disclosure | K5: High | L5: =IFERROR(IF(INDEX(Benchmark!$K$33:$K$62,MATCH($A5,Benchmark!$A$33:$A$62,0))="n/a","No official equivalent",INDEX(Benchmark!$J$33:$J$62,MATCH($A5,Benchmark!$A$33:$A$62,0))&" - "&INDEX(Benchmark!$K$33:$K$62,MATCH($A5,Benchmark!$A$33:$A$62,0))),"") -> Climate strategy - Very High
A6: E02 | B6: GHG Emissions | C6: Tata Power reports Scope 1 and Scope 2 emissions and identifies high Scope 1 emissions from coal-based generation as a key risk. | D6: GHG emissions contribute to climate change and represent an environmental impact of thermal generation. | E6: Higher emissions can increase compliance, monitoring, retrofit and potential carbon-related costs. | F6: Risk + Opportunity | G6: Transition to lower-emission generation, renewable expansion, emissions reduction targets and pollution-control technologies. | H6: TATA POWER FY 2025-26 BRSR | I6: 293 | J6: Company Disclosure | K6: High | L6: =IFERROR(IF(INDEX(Benchmark!$K$33:$K$62,MATCH($A6,Benchmark!$A$33:$A$62,0))="n/a","No official equivalent",INDEX(Benchmark!$J$33:$J$62,MATCH($A6,Benchmark!$A$33:$A$62,0))&" - "&INDEX(Benchmark!$K$33:$K$62,MATCH($A6,Benchmark!$A$33:$A$62,0))),"") -> Emissions management - Very High
A7: E03 | B7: Energy Management | C7: Tata Power identifies high auxiliary power consumption and distribution losses as operational efficiency issues and identifies smart-grid technologies and energy-efficiency measures as opportunities. | D7: Inefficient energy use increases resource consumption and reduces energy efficiency. | E7: Higher energy losses and auxiliary consumption can increase operating costs and reduce efficiency. | F7: Risk + Opportunity | G7: Energy-efficiency measures, operational benchmarking, smart meters, grid digitalization and ISO 50001. | H7: TATA POWER FY 2025-26 BRSR | I7: 293 | J7: Company Disclosure | K7: High | L7: =IFERROR(IF(INDEX(Benchmark!$K$33:$K$62,MATCH($A7,Benchmark!$A$33:$A$62,0))="n/a","No official equivalent",INDEX(Benchmark!$J$33:$J$62,MATCH($A7,Benchmark!$A$33:$A$62,0))&" - "&INDEX(Benchmark!$K$33:$K$62,MATCH($A7,Benchmark!$A$33:$A$62,0))),"") -> Energy management - Very High
A8: E04 | B8: Air Pollution | C8: Tata Power identifies SOx, NOx and particulate/fugitive emissions from coal-based operations as environmental and health concerns. | D8: Air pollutants can affect local air quality, ecosystems and community health. | E8: Tightening emission standards can increase compliance, monitoring and retrofit costs. | F8: Risk + Opportunity | G8: Air Pollution Control Devices, fugitive-emission management, continuous monitoring and FGD/emission-control technologies. | H8: TATA POWER FY 2025-26 BRSR | I8: 293 | J8: Company Disclosure | K8: High | L8: =IFERROR(IF(INDEX(Benchmark!$K$33:$K$62,MATCH($A8,Benchmark!$A$33:$A$62,0))="n/a","No official equivalent",INDEX(Benchmark!$J$33:$J$62,MATCH($A8,Benchmark!$A$33:$A$62,0))&" - "&INDEX(Benchmark!$K$33:$K$62,MATCH($A8,Benchmark!$A$33:$A$62,0))),"") -> Emissions management - Very High
A9: E05 | B9: Water & Effluent | C9: Tata Power's operations depend on water, particularly thermal generation. FY26 water consumption was approximately 266.3 million KL, and the company identifies water stress and discharge requirements as operational and regulatory risks. | D9: Water withdrawal and heated effluent discharge can affect aquatic ecosystems, water quality and availability for surrounding communities. | E9: Water scarcity and tighter discharge regulations can create operational constraints, compliance costs and business interruption risk. | F9: Risk + Opportunity | G9: Water-efficiency measures, wastewater recycling, Zero Liquid Discharge, desalination, rainwater harvesting and 2030 water-neutrality goal. | H9: TATA POWER FY 2025-26 BRSR | I9: 294 | J9: Company Disclosure | K9: High | L9: =IFERROR(IF(INDEX(Benchmark!$K$33:$K$62,MATCH($A9,Benchmark!$A$33:$A$62,0))="n/a","No official equivalent",INDEX(Benchmark!$J$33:$J$62,MATCH($A9,Benchmark!$A$33:$A$62,0))&" - "&INDEX(Benchmark!$K$33:$K$62,MATCH($A9,Benchmark!$A$33:$A$62,0))),"") -> Water and effluent management - Very High
A10: E06 | B10: Biodiversity | C10: Tata Power's generation and infrastructure projects can interact with ecosystems and biodiversity. The company incorporates biodiversity conservation, afforestation, catchment treatment and environmental monitoring into relevant projects. | D10: Power infrastructure can affect habitats, ecosystems and biodiversity. | E10: Biodiversity impacts can create regulatory, approval, project-delay and stakeholder risks. | F10: Risk + Opportunity | G10: Biodiversity conservation, environmental assessments, afforestation, catchment treatment and monitoring. | H10: TATA POWER FY 2025-26 BRSR | I10: 324- 325 | J10: Company Disclosure | K10: High | L10: =IFERROR(IF(INDEX(Benchmark!$K$33:$K$62,MATCH($A10,Benchmark!$A$33:$A$62,0))="n/a","No official equivalent",INDEX(Benchmark!$J$33:$J$62,MATCH($A10,Benchmark!$A$33:$A$62,0))&" - "&INDEX(Benchmark!$K$33:$K$62,MATCH($A10,Benchmark!$A$33:$A$62,0))),"") -> Safeguarding biodiversity - High
A11: E07 | B11: Waste Management | C11: Tata Power identifies major waste streams including fly ash from thermal power plants and chemical sludge from solar PV manufacturing. It also discusses recycling pathways for end-of-life solar panels | D11: Improper waste management can cause pollution and environmental impacts. | E11: Waste-treatment, disposal and compliance requirements create operating costs; circularity can create resource-efficiency opportunities | F11: Risk + Opportunity | G11: Fly-ash utilization, bottom-ash utilization and development of recycling pathways for end-of-life PV panels. | H11: TATA POWER FY 2025-26 BRSR | I11: 323 | J11: Company Disclosure | K11: High | L11: =IFERROR(IF(INDEX(Benchmark!$K$33:$K$62,MATCH($A11,Benchmark!$A$33:$A$62,0))="n/a","No official equivalent",INDEX(Benchmark!$J$33:$J$62,MATCH($A11,Benchmark!$A$33:$A$62,0))&" - "&INDEX(Benchmark!$K$33:$K$62,MATCH($A11,Benchmark!$A$33:$A$62,0))),"") -> Hazardous and toxic waste management - High
A12: E08 | B12: Ash Management | C12: Tata Power identifies fly ash as a major waste stream from thermal power plants and reports its utilization in construction, ready-mix concrete, cement and quarry filling. | D12: Poor ash management can create risks of land, air and water contamination. | E12: Ash handling, disposal and compliance require expenditure, while utilization creates potential cost/resource-efficiency benefits. | F12: Risk + Opportunity | G12: Fly-ash utilization through authorized vendors and increased bottom-ash utilization. | H12: TATA POWER FY 2025-26 BRSR | I12: 323 | J12: Company Disclosure | K12: High | L12: =IFERROR(IF(INDEX(Benchmark!$K$33:$K$62,MATCH($A12,Benchmark!$A$33:$A$62,0))="n/a","No official equivalent",INDEX(Benchmark!$J$33:$J$62,MATCH($A12,Benchmark!$A$33:$A$62,0))&" - "&INDEX(Benchmark!$K$33:$K$62,MATCH($A12,Benchmark!$A$33:$A$62,0))),"") -> No official equivalent
A13: E09 | B13: Land Use | C13: Tata Power identifies the large land footprint associated with solar/wind farms as potentially affecting land use and local ecosystems. | D13: Large energy infrastructure projects can alter land use and affect local ecosystems and communities. | E13: Land availability, approvals, project development and stakeholder issues can affect project timelines and costs. | F13: Risk + Opportunity | G13: Environmental approvals, biodiversity conservation, catchment protection and environmental management measures. | H13: TATA POWER FY 2025-26 BRSR | I13: 294 | J13: Company Disclosure | K13: Medium - High | L13: =IFERROR(IF(INDEX(Benchmark!$K$33:$K$62,MATCH($A13,Benchmark!$A$33:$A$62,0))="n/a","No official equivalent",INDEX(Benchmark!$J$33:$J$62,MATCH($A13,Benchmark!$A$33:$A$62,0))&" - "&INDEX(Benchmark!$K$33:$K$62,MATCH($A13,Benchmark!$A$33:$A$62,0))),"") -> No official equivalent
A14: E10 | B14: Resource Use & Circular Economy. | C14: Tata Power describes resource-efficiency measures and circularity initiatives, including PV-panel end-of-life management, recycling pathways and waste utilization | D14: Efficient resource use reduces waste and pressure on natural resources. | E14: Better resource efficiency can reduce material/waste costs and create opportunities for recovery and recycling. | F14: Risk + Opportunity | G14: Waste utilization, PV recycling pathways and circular-economy initiatives. | H14: TATA POWER FY 2025-26 BRSR | I14: 323 | J14: Company Disclosure | K14: Medium - High | L14: =IFERROR(IF(INDEX(Benchmark!$K$33:$K$62,MATCH($A14,Benchmark!$A$33:$A$62,0))="n/a","No official equivalent",INDEX(Benchmark!$J$33:$J$62,MATCH($A14,Benchmark!$A$33:$A$62,0))&" - "&INDEX(Benchmark!$K$33:$K$62,MATCH($A14,Benchmark!$A$33:$A$62,0))),"") -> Product design and lifecycle management* - Medium
L15: =IFERROR(IF(INDEX(Benchmark!$K$33:$K$62,MATCH($A15,Benchmark!$A$33:$A$62,0))="n/a","No official equivalent",INDEX(Benchmark!$J$33:$J$62,MATCH($A15,Benchmark!$A$33:$A$62,0))&" - "&INDEX(Benchmark!$K$33:$K$62,MATCH($A15,Benchmark!$A$33:$A$62,0))),"")
A16: S01 | B16: Occupational Health & Safety | C16: Tata Power identifies occupational health and safety as a material issue. In FY26, it maintained an Occupational Health & Safety Management System aligned with Tata Group standards and ISO 45001:2018, trained 100% of employees and business-associate workforce on OH&S systems, and conducted 757 safety capability workshops involving 18,920 personnel. | D16: Power generation, transmission and distribution involve significant physical and operational hazards. Workplace incidents can cause injury, health impacts and potentially fatalities. | E16: Safety incidents can lead to medical and compensation costs, litigation, operational disruption, workforce availability issues and reputational damage. | F16: Risk + Opportunity | G16: ISO 45001-aligned OH&S management system, HIRA/JSA, safety training, PPE, audits, automation/mechanisation and business-associate safety programmes. | H16: Tata Power FY2025–26 Integrated Annual Report | I16: 294 -95 | J16: Company Disclosure | K16: High | L16: =IFERROR(IF(INDEX(Benchmark!$K$33:$K$62,MATCH($A16,Benchmark!$A$33:$A$62,0))="n/a","No official equivalent",INDEX(Benchmark!$J$33:$J$62,MATCH($A16,Benchmark!$A$33:$A$62,0))&" - "&INDEX(Benchmark!$K$33:$K$62,MATCH($A16,Benchmark!$A$33:$A$62,0))),"") -> Occupational health and safety - Very High
A17: S02 | B17: Employee Wellbeing | C17: Tata Power describes employee wellbeing, engagement and a safe, inclusive workplace as priorities. FY26 initiatives included mental wellbeing, stress management, financial health, nutrition, preventive healthcare, employee surveys and leadership interactions. | D17: Employee wellbeing affects physical, mental and social health and the quality of the working environment. | E17: Poor employee wellbeing can contribute to absenteeism, lower productivity, turnover and higher workforce costs. | F17: Risk + Opportunity | G17: "A Fuller Life" framework, employee assistance programmes, health screening, counselling, wellbeing initiatives and engagement programmes. | H17: Tata Power FY2025–26 Integrated Annual Report | I17: 125 - 135 | J17: Company Disclosure | K17: High | L17: =IFERROR(IF(INDEX(Benchmark!$K$33:$K$62,MATCH($A17,Benchmark!$A$33:$A$62,0))="n/a","No official equivalent",INDEX(Benchmark!$J$33:$J$62,MATCH($A17,Benchmark!$A$33:$A$62,0))&" - "&INDEX(Benchmark!$K$33:$K$62,MATCH($A17,Benchmark!$A$33:$A$62,0))),"") -> Responsible employer - Medium
A18: S03 | B18: Diversity & Inclusion | C18: Tata Power identifies diversity and inclusion as a material social topic and states that it aims to create an inclusive workplace across levels. FY26 initiatives included women leadership development and targeted inclusion programmes. | D18: Workplace diversity and inclusion affect equality of opportunity, employee experience and representation. | E18: Effective diversity and inclusion can influence talent attraction, retention, engagement and leadership pipeline development. | F18: Risk + Opportunity | G18: Diversity and inclusion programmes, women leadership development, targeted workforce initiatives and inclusive workplace policies. | H18: Tata Power FY2025–26 Integrated Annual Report | I18: 125 - 135 | J18: Company Disclosure | K18: High | L18: =IFERROR(IF(INDEX(Benchmark!$K$33:$K$62,MATCH($A18,Benchmark!$A$33:$A$62,0))="n/a","No official equivalent",INDEX(Benchmark!$J$33:$J$62,MATCH($A18,Benchmark!$A$33:$A$62,0))&" - "&INDEX(Benchmark!$K$33:$K$62,MATCH($A18,Benchmark!$A$33:$A$62,0))),"") -> Diversity and inclusion in workplace - Medium
A19: S04 | B19: Talent Development | C19: Tata Power identifies employee retention, engagement and talent development as material and reports structured learning, leadership development, technical training and internal mobility programmes. | D19: Training and development improve employee capability, employability and career progression. | E19: Skill development supports productivity, operational capability, retention and the ability to execute the energy transition. | F19: Risk + Opportunity | G19: Structured learning, leadership programmes, technical training, WILP and internal mobility. | H19: Tata Power FY2025–26 Integrated Annual Report | I19: 125 - 135 | J19: Company Disclosure | K19: High | L19: =IFERROR(IF(INDEX(Benchmark!$K$33:$K$62,MATCH($A19,Benchmark!$A$33:$A$62,0))="n/a","No official equivalent",INDEX(Benchmark!$J$33:$J$62,MATCH($A19,Benchmark!$A$33:$A$62,0))&" - "&INDEX(Benchmark!$K$33:$K$62,MATCH($A19,Benchmark!$A$33:$A$62,0))),"") -> Employee retention, engagement and talent development - High
A20: S05 | B20: Labour Practices | C20: Tata Power identifies labour management as a material topic and recognizes potential operational disruption from labour issues. It states that labour compliance is maintained according to regulatory requirements and global standards such as ILO principles. | D20: Poor labour practices can affect employee rights, working conditions and industrial relations. | E20: Labour disputes or workforce disruption can cause downtime, productivity losses and additional operating costs. | F20: Risk | G20: Labour compliance, alignment with regulatory requirements and international labour standards. | H20: Tata Power FY2025–26 BRSR | I20: 294 - 295 | J20: Company Disclosure | K20: High | L20: =IFERROR(IF(INDEX(Benchmark!$K$33:$K$62,MATCH($A20,Benchmark!$A$33:$A$62,0))="n/a","No official equivalent",INDEX(Benchmark!$J$33:$J$62,MATCH($A20,Benchmark!$A$33:$A$62,0))&" - "&INDEX(Benchmark!$K$33:$K$62,MATCH($A20,Benchmark!$A$33:$A$62,0))),"") -> Labour management - High
A21: S06 | B21: Human Rights | C21: Tata Power's Human Rights Commitment Framework covers dignity, freedom of association, collective bargaining, non-discrimination, prohibition of child and forced labour, and alignment with ILO and UN Global Compact principles. | D21: Power-sector operations and supply chains can affect workers, communities and other stakeholders, making human-rights protection important. | E21: Human-rights violations can create legal, operational, reputational and stakeholder risks. | F21: Risk | G21: Human Rights Commitment Framework, human-rights assessments, training and alignment with international labour standards. | H21: Tata Power FY2025–26 Integrated Annual Report | I21: ~125–135 / 298–299 | J21: Company Disclosure | K21: High | L21: =IFERROR(IF(INDEX(Benchmark!$K$33:$K$62,MATCH($A21,Benchmark!$A$33:$A$62,0))="n/a","No official equivalent",INDEX(Benchmark!$J$33:$J$62,MATCH($A21,Benchmark!$A$33:$A$62,0))&" - "&INDEX(Benchmark!$K$33:$K$62,MATCH($A21,Benchmark!$A$33:$A$62,0))),"") -> Human rights - High
A22: S07 | B22: Community Impact | C22: Tata Power states that its community initiatives focus on inclusive growth and resilience, particularly in underserved communities. Its CSR approach covers areas including education, employability, entrepreneurship and essential enablers. (FY26 CSR expenditure was reported at approximately ₹100.54 crore) | D22: Large energy projects can affect communities through employment, infrastructure, land use, environmental impacts and access to energy. | E22: Weak community relationships can create stakeholder opposition, delays, reputational issues and project-development risks. | F22: Risk + Opportunity | G22: CSR programmes, community engagement and initiatives focused on education, employment, entrepreneurship and essential enablers. | H22: Tata Power FY2025–26 Integrated Annual Report | I22: 292 / 146–167 | J22: Company disclosure | K22: High | L22: =IFERROR(IF(INDEX(Benchmark!$K$33:$K$62,MATCH($A22,Benchmark!$A$33:$A$62,0))="n/a","No official equivalent",INDEX(Benchmark!$J$33:$J$62,MATCH($A22,Benchmark!$A$33:$A$62,0))&" - "&INDEX(Benchmark!$K$33:$K$62,MATCH($A22,Benchmark!$A$33:$A$62,0))),"") -> Building sustainable communities - High
A23: S08 | B23: Access & Affordability | C23: Tata Power identifies access and affordability as a newly added material topic, reflecting the importance of inclusive access to reliable and affordable electricity. (The company reports a distribution customer base of 13.1+ million and emphasizes reliable and affordable energy access) | D23: Electricity access and affordability directly affect household welfare, economic opportunity and quality of life. | E23: Affordability and access influence demand, customer retention, collections and the long-term sustainability of distribution businesses. | F23: Risk + Opportunity | G23: Distribution network expansion, digitalisation, smart metering, customer-centric services, rooftop solar and clean-energy solutions. | H23: Tata Power FY2025–26 Integrated Annual Report / Materiality Assessment | I23: 80 - 90 | J23: Company disclosure | K23: High | L23: =IFERROR(IF(INDEX(Benchmark!$K$33:$K$62,MATCH($A23,Benchmark!$A$33:$A$62,0))="n/a","No official equivalent",INDEX(Benchmark!$J$33:$J$62,MATCH($A23,Benchmark!$A$33:$A$62,0))&" - "&INDEX(Benchmark!$K$33:$K$62,MATCH($A23,Benchmark!$A$33:$A$62,0))),"") -> Access and affordability* - High
A24: S09 | B24: Customer Welfare | C24: Tata Power identifies customer relationship management as a material topic. The company states that poor service quality could lead to customer loss and uses multiple customer-feedback channels. Its FY26 C.A.R.E. initiative covered 10,343 employees across 22 locations in the Odisha DISCOMs to strengthen customer-centric service delivery. | D24: Electricity customers depend on reliable, responsive and fair service. | E24: Poor customer experience can result in customer dissatisfaction, complaints, collection issues, reputational damage and revenue impacts. | F24: Risk + Opportunity | G24: Customer-feedback mechanisms, C.A.R.E. initiative, digital platforms and customer-centric service programmes. | H24: Tata Power FY2025–26 Integrated Annual Report | I24: 110 - 119 | J24: Company disclosure | K24: High | L24: =IFERROR(IF(INDEX(Benchmark!$K$33:$K$62,MATCH($A24,Benchmark!$A$33:$A$62,0))="n/a","No official equivalent",INDEX(Benchmark!$J$33:$J$62,MATCH($A24,Benchmark!$A$33:$A$62,0))&" - "&INDEX(Benchmark!$K$33:$K$62,MATCH($A24,Benchmark!$A$33:$A$62,0))),"") -> Customer relationship management - High
A25: S10 | B25: Energy Reliability | C25: Tata Power operates generation, transmission and distribution businesses and emphasizes reliable energy supply, resilient distribution networks and grid infrastructure. Its FY26 strategy includes strengthening distribution businesses and developing resilient energy infrastructure. | D25: Electricity reliability affects households, businesses, public services and economic activity. | E25: Power interruptions can cause service penalties, customer dissatisfaction, operational losses and reputational damage. | F25: Risk + Opportunity | G25: Grid modernization, smart meters, digitalisation, transmission expansion and distribution network improvements. | H25: Tata Power FY2025–26 Integrated Annual Report | I25: 294 | J25: Company disclosure | K25: High | L25: =IFERROR(IF(INDEX(Benchmark!$K$33:$K$62,MATCH($A25,Benchmark!$A$33:$A$62,0))="n/a","No official equivalent",INDEX(Benchmark!$J$33:$J$62,MATCH($A25,Benchmark!$A$33:$A$62,0))&" - "&INDEX(Benchmark!$K$33:$K$62,MATCH($A25,Benchmark!$A$33:$A$62,0))),"") -> Continuous and affordable green power - Very High
L26: =IFERROR(IF(INDEX(Benchmark!$K$33:$K$62,MATCH($A26,Benchmark!$A$33:$A$62,0))="n/a","No official equivalent",INDEX(Benchmark!$J$33:$J$62,MATCH($A26,Benchmark!$A$33:$A$62,0))&" - "&INDEX(Benchmark!$K$33:$K$62,MATCH($A26,Benchmark!$A$33:$A$62,0))),"")
A27: G01 | B27: Business Ethics — Anti-corruption | C27: Tata Power identifies Ethical Business Conduct as a material governance topic. The Tata Code of Conduct (TCoC) provides the framework for ethical behaviour, while employees, customers and suppliers are expected to adhere to relevant principles. | D27: Ethical misconduct, bribery or corruption can negatively affect employees, business partners, customers and institutional trust. | E27: Ethical violations can result in penalties, litigation, loss of business relationships and reputational damage. | F27: Risk | G27: TCoC, anti-bribery and anti-corruption training, whistleblower mechanism, ethics investigations and annual compliance processes. | H27: FY26 Integrated Annual Report / Tata Power Ethics | I27: 82; Ethics section | J27: Tata Power Annual Report / Corporate website | K27: High | L27: =IFERROR(IF(INDEX(Benchmark!$K$33:$K$62,MATCH($A27,Benchmark!$A$33:$A$62,0))="n/a","No official equivalent",INDEX(Benchmark!$J$33:$J$62,MATCH($A27,Benchmark!$A$33:$A$62,0))&" - "&INDEX(Benchmark!$K$33:$K$62,MATCH($A27,Benchmark!$A$33:$A$62,0))),"") -> Ethical business conduct - Very High
A28: G02 | B28: Regulatory Compliance — Legal & Regulatory | C28: Tata Power identifies Regulatory Compliance and Landscape as a material topic. The power sector is highly regulated across generation, transmission, distribution, environment, safety and consumer matters. | D28: Non-compliance can affect customers, employees, communities and the environment. | E28: Regulatory changes or non-compliance can lead to penalties, operational disruption, additional compliance costs and project delays. | F28: Risk | G28: Regulatory monitoring, policy advocacy, compliance mechanisms and engagement with regulators and policymakers. | H28: FY26 Integrated Annual Report | I28: 82–83 | J28: Tata Power Annual Report | K28: High | L28: =IFERROR(IF(INDEX(Benchmark!$K$33:$K$62,MATCH($A28,Benchmark!$A$33:$A$62,0))="n/a","No official equivalent",INDEX(Benchmark!$J$33:$J$62,MATCH($A28,Benchmark!$A$33:$A$62,0))&" - "&INDEX(Benchmark!$K$33:$K$62,MATCH($A28,Benchmark!$A$33:$A$62,0))),"") -> Regulatory compliance and landscape - High
A29: G03 | B29: ESG Governance — Board Oversight | C29: Tata Power identifies ESG Governance as a very high-priority material issue. Its governance structure integrates sustainability considerations into strategic decision-making and oversight. | D29: Strong ESG governance influences how environmental and social impacts are identified, managed and monitored. | E29: Weak ESG integration can affect investor confidence, access to capital, compliance and strategic decision-making. | F29: Risk + Opportunity | G29: CSR & Sustainability Board Committee, ESG governance structure, leadership review and integration of ESG into business strategy. | H29: FY26 BRSR / Integrated Annual Report | I29: 295; 82 | J29: Tata Power BRSR / Annual Report | K29: High | L29: =IFERROR(IF(INDEX(Benchmark!$K$33:$K$62,MATCH($A29,Benchmark!$A$33:$A$62,0))="n/a","No official equivalent",INDEX(Benchmark!$J$33:$J$62,MATCH($A29,Benchmark!$A$33:$A$62,0))&" - "&INDEX(Benchmark!$K$33:$K$62,MATCH($A29,Benchmark!$A$33:$A$62,0))),"") -> ESG governance - Very High
A30: G04 | B30: Risk Management — ESG Risk | C30: Tata Power identifies Risk Management and BCDMP (Business Continuity & Disaster Management Plan) as a material topic. Its operations face physical, operational, climate, cyber, regulatory and business-continuity risks. | D30: Effective risk management reduces potential impacts on employees, communities, customers and infrastructure. | E30: Failure to manage material risks can result in business interruption, revenue loss, asset damage and higher risk costs. | F30: Risk + Opportunity | G30: Enterprise risk management, BCDMP, periodic mock exercises and integration of emerging risks into business planning. | H30: FY26 Integrated Annual Report | I30: 83 | J30: Tata Power Annual Report | K30: High | L30: =IFERROR(IF(INDEX(Benchmark!$K$33:$K$62,MATCH($A30,Benchmark!$A$33:$A$62,0))="n/a","No official equivalent",INDEX(Benchmark!$J$33:$J$62,MATCH($A30,Benchmark!$A$33:$A$62,0))&" - "&INDEX(Benchmark!$K$33:$K$62,MATCH($A30,Benchmark!$A$33:$A$62,0))),"") -> Risk management and BCDMP - High
A31: G05 | B31: Cybersecurity — Cyber Risk | C31: Tata Power identifies Digitalisation, Data Privacy and Cyber Security as a material topic. Increasing digitalisation of power generation, grids, smart meters and customer platforms increases cyber exposure. | D31: Cyber incidents can affect customers, employees, critical infrastructure and continuity of electricity services. | E31: Cyberattacks can result in operational disruption, financial losses, regulatory consequences, data breaches and reputational damage. | F31: Risk | G31: Information-security architecture, access controls, cybersecurity measures, awareness and protection of customer/operational data. | H31: FY26 BRSR / Integrated Annual Report | I31: 295; 82 | J31: Tata Power BRSR / Annual Report | K31: High | L31: =IFERROR(IF(INDEX(Benchmark!$K$33:$K$62,MATCH($A31,Benchmark!$A$33:$A$62,0))="n/a","No official equivalent",INDEX(Benchmark!$J$33:$J$62,MATCH($A31,Benchmark!$A$33:$A$62,0))&" - "&INDEX(Benchmark!$K$33:$K$62,MATCH($A31,Benchmark!$A$33:$A$62,0))),"") -> Digitalisation, data privacy and cyber security - Very High
A32: G06 | B32: Data Privacy — Customer Data | C32: Tata Power expanded its earlier digitalisation/cybersecurity topic to explicitly include Data Privacy in FY26, recognising the importance of protecting personal and operational data. | D32: Improper use or disclosure of personal data can directly affect customers, employees and other stakeholders. | E32: Data breaches can create regulatory penalties, remediation costs, customer loss and reputational damage. | F32: Risk | G32: Customer privacy controls, information-security framework and compliance with India's Digital Personal Data Protection Act, 2023. | H32: FY26 Integrated Annual Report | I32: 82 | J32: Tata Power Annual Report | K32: High | L32: =IFERROR(IF(INDEX(Benchmark!$K$33:$K$62,MATCH($A32,Benchmark!$A$33:$A$62,0))="n/a","No official equivalent",INDEX(Benchmark!$J$33:$J$62,MATCH($A32,Benchmark!$A$33:$A$62,0))&" - "&INDEX(Benchmark!$K$33:$K$62,MATCH($A32,Benchmark!$A$33:$A$62,0))),"") -> Digitalisation, data privacy and cyber security - Very High
A33: G07 | B33: Responsible Supply Chain — Supplier ESG | C33: Tata Power identifies Responsible Supply Chain as a material topic. Its supplier ESG framework considers environmental, social, ethical and country-specific risks and screens suppliers accordingly. | D33: Supply-chain practices can create impacts related to labour, human rights, environment, health & safety and responsible sourcing. | E33: Supplier failures can cause disruptions, quality issues, reputational damage and increased procurement costs. | F33: Risk + Opportunity | G33: ESG screening, supplier assessments, responsible supply-chain policy, supplier ESG awareness and development programmes. | H33: FY26 Integrated Annual Report / Tata Power Supplier ESG | I33: 82; Supplier section | J33: Tata Power Annual Report / Corporate website | K33: High | L33: =IFERROR(IF(INDEX(Benchmark!$K$33:$K$62,MATCH($A33,Benchmark!$A$33:$A$62,0))="n/a","No official equivalent",INDEX(Benchmark!$J$33:$J$62,MATCH($A33,Benchmark!$A$33:$A$62,0))&" - "&INDEX(Benchmark!$K$33:$K$62,MATCH($A33,Benchmark!$A$33:$A$62,0))),"") -> Responsible supply chain - High
A34: G08 | B34: Transparency — ESG Disclosure & Accountability | C34: Tata Power identifies Transparency and Accountability as a material governance topic. FY26 reporting includes integrated reporting, BRSR disclosures and enhanced ESG reporting. | D34: Transparent reporting supports stakeholder understanding, accountability and informed engagement. | E34: Weak transparency can reduce investor confidence and increase regulatory/reputational risk. | F34: Risk + Opportunity | G34: Integrated reporting, BRSR, assurance, stakeholder dialogue and enhanced ESG disclosures. | H34: FY26 Integrated Annual Report | I34: 82–83 | J34: Tata Power Annual Report | K34: High | L34: =IFERROR(IF(INDEX(Benchmark!$K$33:$K$62,MATCH($A34,Benchmark!$A$33:$A$62,0))="n/a","No official equivalent",INDEX(Benchmark!$J$33:$J$62,MATCH($A34,Benchmark!$A$33:$A$62,0))&" - "&INDEX(Benchmark!$K$33:$K$62,MATCH($A34,Benchmark!$A$33:$A$62,0))),"") -> Transparency and accountability - High
A35: G09 | B35: Innovation — Clean Technology | C35: Tata Power identifies Innovation and Collaborations as a material topic and highlights technologies such as CCUS, Green Hydrogen, SMR and other emerging solutions, along with collaboration with external technology partners. | D35: Clean-technology innovation can reduce environmental impacts and support the energy transition. | E35: Successful innovation can create new revenue streams and improve efficiency; failure to adapt can create technology and competitiveness risks. | F35: Risk + Opportunity | G35: Partnerships with startups, technology firms, academic institutions and other organisations; development/adoption of emerging clean technologies. | H35: FY26 Integrated Annual Report | I35: 83 | J35: Tata Power Annual Report | K35: High | L35: =IFERROR(IF(INDEX(Benchmark!$K$33:$K$62,MATCH($A35,Benchmark!$A$33:$A$62,0))="n/a","No official equivalent",INDEX(Benchmark!$J$33:$J$62,MATCH($A35,Benchmark!$A$33:$A$62,0))&" - "&INDEX(Benchmark!$K$33:$K$62,MATCH($A35,Benchmark!$A$33:$A$62,0))),"") -> Innovation and collaborations - High
A36: G10 | B36: Creating Economic Value | C36: For our independent DMA, this topic captures responsible economic conduct, value creation, capital allocation and tax-related stakeholder responsibilities. Tata Power's official FY26 material topic is Creating Economic Value; this topic is now labelled to match it (previously “Responsible Tax & Economic Conduct”). No tax-specific evidence was found in the sources reviewed (see Sources & Checks). | D36: Responsible economic conduct affects employees, suppliers, governments, investors and communities through value distribution and economic contribution. | E36: Efficient capital allocation and sustainable value creation influence long-term financial resilience and shareholder value. | F36: Opportunity + Risk | G36: Operational excellence, balance-sheet strengthening, efficient capital allocation and creation of economic value. | H36: FY26 Integrated Annual Report | I36: 82–83 | J36: Tata Power Annual Report | K36: High | L36: =IFERROR(IF(INDEX(Benchmark!$K$33:$K$62,MATCH($A36,Benchmark!$A$33:$A$62,0))="n/a","No official equivalent",INDEX(Benchmark!$J$33:$J$62,MATCH($A36,Benchmark!$A$33:$A$62,0))&" - "&INDEX(Benchmark!$K$33:$K$62,MATCH($A36,Benchmark!$A$33:$A$62,0))),"") -> Creating economic value - Very High

Sheet Scoring Methodology
A1: IMPACT SCORING METHODOLOGY
A3: Severity Score | B3: Classification | C3: Definition | E3: Likelihood factors
A4: 1 | B4: Very Low | C4: Minimal impact | E4: 1 | F4: 2 | G4: 3 | H4: 4 | I4: 5
A5: 2 | B5: Low | C5: Limited impact | E5: 0.6 | F5: 0.75 | G5: 0.85 | H5: 0.95 | I5: 1
A6: 3 | B6: Moderate | C6: Noticeable but manageable
A7: 4 | B7: High | C7: Significant stakeholder impact | E7: Inherent Impact = (Severity + Scope + Irremediability) / 3
A8: 5 | B8: Very High | C8: Severe/critical impact; potentially irreversible | E8: Impact Score = [(Severity + Scope + Irremediability) / 3] × Likelihood Factor
E10: Impact Score | F10: 1.00–1.99 | G10: 2.00–2.99 | H10: 3.00–3.99 | I10: 4.00–5.00
A11: Irremediability Score | B11: Classification | C11: Definition | E11: Classification | F11: Low | G11: Moderate | H11: High | I11: Very High
A12: 1 | B12: Easily Reversible | C12: Impact can be completely corrected quickly
A13: 2 | B13: Mostly Reversible | C13: Can be restored with limited intervention
A14: 3 | B14: Partially Reversible | C14: Restoration is possible but requires significant effort
A15: 4 | B15: Difficult to Reverse | C15: Restoration is difficult, costly or uncertain
A16: 5 | B16: Irreversible | C16: Cannot realistically be restored to the original condition
A18: Likelihood Score | B18: Classification | C18: Definition
A19: 1 | B19: Very Unlikely | C19: Remote possibility
A20: 2 | B20: Unlikely | C20: Could occur, but not expected
A21: 3 | B21: Possible | C21: Reasonably possible
A22: 4 | B22: Likely | C22: Expected to occur under normal/foreseeable conditions
A23: 5 | B23: Almost Certain | C23: Highly likely / ongoing or recurrent exposure
A25: Scope Score | B25: Classification | C25: Definition
A26: 1 | B26: Very Limited | C26: Single site / very small group
A27: 2 | B27: Limited | C27: One location or limited stakeholder group
A28: 3 | B28: Moderate | C28: Multiple sites or stakeholder groups
A29: 4 | B29: Wide | C29: Multiple regions / large stakeholder population
A30: 5 | B30: Very Wide / Systemic | C30: Enterprise-wide, national, value-chain or potentially global

Sheet Impact Scoring
A1: Tata Power — Double Materiality Assessment | Impact Materiality Scoring
A2: Impact Score = Average (Severity + Scope + Irremediability) × Likelihood Factor
A4: ID | B4: Category | C4: ESG Topic | D4: Impact Description | E4: Affected Stakeholders | F4: Severity | G4: Scope | H4: Irremediability | I4: Likelihood | J4: Impact Score | K4: Materiality | L4: Scoring Rationale | M4: Evidence Reference
A5: E01 | B5: Environmental | C5: Climate Change | D5: Thermal generation contributes to GHG emissions and climate-related impacts, while transition to cleaner energy affects the environmental footprint. | E5: Environment, Communities, Customers, Society | F5: 5 | G5: 5 | H5: 5 | I5: 5 | J5: =AVERAGE(F5:H5)*CHOOSE(I5,0.6,0.75,0.85,0.95,1) -> 5 | K5: =IF(J5>=4,"Very High",IF(J5>=3,"High",IF(J5>=2,"Moderate","Low"))) -> Very High | L5: Global-scale impact with potentially irreversible consequences and high likelihood. | M5: FY26 BRSR p.293
A6: E02 | B6: Environmental | C6: GHG Emissions | D6: Coal-based generation contributes materially to Scope 1 emissions and associated climate impacts. | E6: Environment, Communities, Society | F6: 5 | G6: 5 | H6: 5 | I6: 5 | J6: =AVERAGE(F6:H6)*CHOOSE(I6,0.6,0.75,0.85,0.95,1) -> 5 | K6: =IF(J6>=4,"Very High",IF(J6>=3,"High",IF(J6>=2,"Moderate","Low"))) -> Very High | L6: High severity, broad scope and long-term climate consequences. | M6: FY26 BRSR p.293
A7: E03 | B7: Environmental | C7: Energy Management | D7: Inefficient energy use can increase resource consumption and environmental footprint across operations. | E7: Environment, Customers, Communities | F7: 3 | G7: 4 | H7: 3 | I7: 5 | J7: =AVERAGE(F7:H7)*CHOOSE(I7,0.6,0.75,0.85,0.95,1) -> 3.3333333 | K7: =IF(J7>=4,"Very High",IF(J7>=3,"High",IF(J7>=2,"Moderate","Low"))) -> High | L7: Significant operational footprint and high relevance to a power-sector business. | M7: FY26 BRSR p.293
A8: E04 | B8: Environmental | C8: Air Pollution | D8: Thermal operations can generate SOx, NOx and particulate emissions affecting air quality. | E8: Employees, Communities, Environment | F8: 5 | G8: 4 | H8: 4 | I8: 4 | J8: =AVERAGE(F8:H8)*CHOOSE(I8,0.6,0.75,0.85,0.95,1) -> 4.1166667 | K8: =IF(J8>=4,"Very High",IF(J8>=3,"High",IF(J8>=2,"Moderate","Low"))) -> Very High | L8: Potentially severe health and environmental consequences with significant local exposure. | M8: FY26 BRSR p.293
A9: E05 | B9: Environmental | C9: Water & Effluent | D9: Thermal generation can require significant water withdrawal and consumption, particularly in water-stressed areas. | E9: Communities, Environment, Water Users | F9: 4 | G9: 4 | H9: 4 | I9: 4 | J9: =AVERAGE(F9:H9)*CHOOSE(I9,0.6,0.75,0.85,0.95,1) -> 3.8 | K9: =IF(J9>=4,"Very High",IF(J9>=3,"High",IF(J9>=2,"Moderate","Low"))) -> High | L9: Significant resource dependence and potential ecosystem/community impacts. | M9: FY26 BRSR p.294
A10: E06 | B10: Environmental | C10: Biodiversity | D10: Energy infrastructure and land-intensive projects can affect ecosystems, habitats and biodiversity. | E10: Environment, Communities | F10: 4 | G10: 4 | H10: 5 | I10: 3 | J10: =AVERAGE(F10:H10)*CHOOSE(I10,0.6,0.75,0.85,0.95,1) -> 3.6833333 | K10: =IF(J10>=4,"Very High",IF(J10>=3,"High",IF(J10>=2,"Moderate","Low"))) -> High | L10: Potentially difficult-to-reverse ecological impacts, although likelihood varies by project/location. | M10: FY26 Integrated Report
A11: E07 | B11: Environmental | C11: Waste Management | D11: Generation and disposal of operational and manufacturing waste can create environmental and community impacts. | E11: Environment, Communities, Workers | F11: 3 | G11: 4 | H11: 3 | I11: 4 | J11: =AVERAGE(F11:H11)*CHOOSE(I11,0.6,0.75,0.85,0.95,1) -> 3.1666667 | K11: =IF(J11>=4,"Very High",IF(J11>=3,"High",IF(J11>=2,"Moderate","Low"))) -> High | L11: Waste impacts can occur across multiple operations and require effective management. | M11: FY26 Integrated Report
A12: E08 | B12: Environmental | C12: Ash Management | D12: Coal-based operations generate fly ash and bottom ash requiring storage, transportation and beneficial utilisation. | E12: Communities, Environment, Workers | F12: 4 | G12: 4 | H12: 3 | I12: 4 | J12: =AVERAGE(F12:H12)*CHOOSE(I12,0.6,0.75,0.85,0.95,1) -> 3.4833333 | K12: =IF(J12>=4,"Very High",IF(J12>=3,"High",IF(J12>=2,"Moderate","Low"))) -> High | L12: Large-volume waste stream with potential land, air and water impacts. | M12: FY26 Integrated Report
A13: E09 | B13: Environmental | C13: Land Use | D13: Solar, wind and other infrastructure projects require land and may affect land use, ecosystems and local communities. | E13: Communities, Land Users, Environment | F13: 3 | G13: 4 | H13: 4 | I13: 3 | J13: =AVERAGE(F13:H13)*CHOOSE(I13,0.6,0.75,0.85,0.95,1) -> 3.1166667 | K13: =IF(J13>=4,"Very High",IF(J13>=3,"High",IF(J13>=2,"Moderate","Low"))) -> High | L13: Impacts can be geographically significant and difficult to reverse depending on project location. | M13: FY26 BRSR p.294
A14: E10 | B14: Environmental | C14: Resource Use & Circular Economy | D14: Use of materials and management of end-of-life equipment creates opportunities and impacts related to resource efficiency and circularity. | E14: Environment, Suppliers, Communities | F14: 3 | G14: 4 | H14: 3 | I14: 4 | J14: =AVERAGE(F14:H14)*CHOOSE(I14,0.6,0.75,0.85,0.95,1) -> 3.1666667 | K14: =IF(J14>=4,"Very High",IF(J14>=3,"High",IF(J14>=2,"Moderate","Low"))) -> High | L14: Resource consumption occurs across the value chain and circularity can reduce environmental pressure. | M14: FY26 Integrated Report
A15: S01 | B15: Social | C15: Occupational Health & Safety | D15: Generation, transmission, distribution and project activities expose workers to electrical, machinery, height and other occupational hazards. | E15: Employees, Workers, Contractors | F15: 5 | G15: 4 | H15: 5 | I15: 4 | J15: =AVERAGE(F15:H15)*CHOOSE(I15,0.6,0.75,0.85,0.95,1) -> 4.4333333 | K15: =IF(J15>=4,"Very High",IF(J15>=3,"High",IF(J15>=2,"Moderate","Low"))) -> Very High | L15: Potential for severe or fatal consequences; impacts can be irreversible. | M15: FY26 BRSR pp.294–295
A16: S02 | B16: Social | C16: Employee Health, Wellbeing & Engagement | D16: Employee physical, mental, social and financial wellbeing can be affected by workplace conditions and organisational practices. | E16: Employees, Families | F16: 3 | G16: 4 | H16: 3 | I16: 4 | J16: =AVERAGE(F16:H16)*CHOOSE(I16,0.6,0.75,0.85,0.95,1) -> 3.1666667 | K16: =IF(J16>=4,"Very High",IF(J16>=3,"High",IF(J16>=2,"Moderate","Low"))) -> High | L16: Broad workforce exposure with potential effects on wellbeing and quality of working life. | M16: FY26 Integrated Report — People
... A34: G10 | B34: Governance | C34: Creating Economic Value | D34: Economic value creation and responsible economic conduct influence employees, suppliers, governments, investors and communities. | E34: Employees, Suppliers, Government, Investors, Communities | F34: 3 | G34: 5 | H34: 3 | I34: 3 | J34: =AVERAGE(F34:H34)*CHOOSE(I34,0.6,0.75,0.85,0.95,1) -> 3.1166667 | K34: =IF(J34>=4,"Very High",IF(J34>=3,"High",IF(J34>=2,"Moderate","Low"))) -> High | L34: Broad stakeholder relevance but comparatively indirect impact on people and environment. | M34: FY26 Integrated Report pp.82–83

Sheet Financial Methodology
A1: FINANCIAL SCORING METHODOLOGY
A3: Likelihood factors | G3: Magnitude Score | H3: Classification | I3: Meaning
A4: 1 | B4: 2 | C4: 3 | D4: 4 | E4: 5 | G4: 1 | H4: Very Low | I4: Minimal financial effect; unlikely to meaningfully affect business performance
A5: 0.6 | B5: 0.75 | C5: 0.85 | D5: 0.95 | E5: 1 | G5: 2 | H5: Low | I5: Limited financial effect; manageable within normal operations
G6: 3 | H6: Moderate | I6: Could meaningfully affect a business unit, cost base, revenue or project economics
A7: Financial Score | B7: 1.00–1.99 | C7: 2.00–2.99 | D7: 3.00–3.99 | E7: 4.00–5.00 | G7: 4 | H7: High | I7: Could materially affect profitability, cash flows, assets, liabilities, capex or financing
A8: Classification | B8: Low | C8: Moderate | D8: High | E8: Very High | G8: 5 | H8: Very High | I8: Potentially major enterprise-level financial effect, including substantial asset impairment, revenue disruption or capital requirements
A11: Score | B11: Time Horizon | C11: Definition
A12: 1 | B12: Very Long Term | C12: >10 years
A13: 2 | B13: Long Term | C13: 5–10 years
A14: 3 | B14: Medium Term | C14: 3–5 years
A15: 4 | B15: Short Term | C15: 1–3 years
A16: 5 | B16: Immediate / Current | C16: <1 year / already occurring

Sheet Financial Scoring
A1: Tata Power — Financial Materiality Assessment
A2: Financial Scoring of ESG Topics | FY2025–26
A4: ID | B4: ESG Topic | C4: Magnitude | D4: Likelihood | E4: Time Horizon | F4: Financial Score | G4: Classification
A5: E01 | B5: Climate Change | C5: 5 | D5: 5 | E5: 3–5 years | F5: =C5*CHOOSE(D5,0.6,0.75,0.85,0.95,1) -> 5 | G5: =IF(F5>=4,"Very High",IF(F5>=3,"High",IF(F5>=2,"Moderate","Low"))) -> Very High
A6: E02 | B6: GHG Emissions | C6: 5 | D6: 5 | E6: 3–5 years | F6: =C6*CHOOSE(D6,0.6,0.75,0.85,0.95,1) -> 5 | G6: =IF(F6>=4,"Very High",IF(F6>=3,"High",IF(F6>=2,"Moderate","Low"))) -> Very High
A7: E03 | B7: Energy Management | C7: 4 | D7: 5 | E7: 1–3 years | F7: =C7*CHOOSE(D7,0.6,0.75,0.85,0.95,1) -> 4 | G7: =IF(F7>=4,"Very High",IF(F7>=3,"High",IF(F7>=2,"Moderate","Low"))) -> Very High
A8: E04 | B8: Air Pollution | C8: 4 | D8: 4 | E8: 1–3 years | F8: =C8*CHOOSE(D8,0.6,0.75,0.85,0.95,1) -> 3.8 | G8: =IF(F8>=4,"Very High",IF(F8>=3,"High",IF(F8>=2,"Moderate","Low"))) -> High
A9: E05 | B9: Water & Effluent | C9: 4 | D9: 4 | E9: 1–3 years | F9: =C9*CHOOSE(D9,0.6,0.75,0.85,0.95,1) -> 3.8 | G9: =IF(F9>=4,"Very High",IF(F9>=3,"High",IF(F9>=2,"Moderate","Low"))) -> High
A10: E06 | B10: Biodiversity | C10: 3 | D10: 3 | E10: 5–10 years | F10: =C10*CHOOSE(D10,0.6,0.75,0.85,0.95,1) -> 2.55 | G10: =IF(F10>=4,"Very High",IF(F10>=3,"High",IF(F10>=2,"Moderate","Low"))) -> Moderate
A11: E07 | B11: Waste Management | C11: 3 | D11: 4 | E11: 1–3 years | F11: =C11*CHOOSE(D11,0.6,0.75,0.85,0.95,1) -> 2.85 | G11: =IF(F11>=4,"Very High",IF(F11>=3,"High",IF(F11>=2,"Moderate","Low"))) -> Moderate
A12: E08 | B12: Ash Management | C12: 4 | D12: 4 | E12: 1–3 years | F12: =C12*CHOOSE(D12,0.6,0.75,0.85,0.95,1) -> 3.8 | G12: =IF(F12>=4,"Very High",IF(F12>=3,"High",IF(F12>=2,"Moderate","Low"))) -> High
A13: E09 | B13: Land Use | C13: 3 | D13: 3 | E13: 3–5 years | F13: =C13*CHOOSE(D13,0.6,0.75,0.85,0.95,1) -> 2.55 | G13: =IF(F13>=4,"Very High",IF(F13>=3,"High",IF(F13>=2,"Moderate","Low"))) -> Moderate
A14: E10 | B14: Resource Use & Circular Economy | C14: 3 | D14: 4 | E14: 3–5 years | F14: =C14*CHOOSE(D14,0.6,0.75,0.85,0.95,1) -> 2.85 | G14: =IF(F14>=4,"Very High",IF(F14>=3,"High",IF(F14>=2,"Moderate","Low"))) -> Moderate
A15: S01 | B15: Occupational Health & Safety | C15: 5 | D15: 4 | E15: 1–3 years | F15: =C15*CHOOSE(D15,0.6,0.75,0.85,0.95,1) -> 4.75 | G15: =IF(F15>=4,"Very High",IF(F15>=3,"High",IF(F15>=2,"Moderate","Low"))) -> Very High
A16: S02 | B16: Employee Health, Wellbeing & Engagement | C16: 3 | D16: 4 | E16: 1–3 years | F16: =C16*CHOOSE(D16,0.6,0.75,0.85,0.95,1) -> 2.85 | G16: =IF(F16>=4,"Very High",IF(F16>=3,"High",IF(F16>=2,"Moderate","Low"))) -> Moderate
... A34: G10 | B34: Creating Economic Value | C34: 4 | D34: 3 | E34: 1–3 years | F34: =C34*CHOOSE(D34,0.6,0.75,0.85,0.95,1) -> 3.4 | G34: =IF(F34>=4,"Very High",IF(F34>=3,"High",IF(F34>=2,"Moderate","Low"))) -> High

Sheet DMA Matrix
A1: Tata Power — Double Materiality Assessment
A2: Impact & Financial Materiality of ESG Topics | FY2025–26 | J2: Vertical Threshold | M2: Horizontal Threshold
J3: Financial X | K3: Impact Y | M3: Financial X | N3: Impact Y
A4: ID | B4: Category | C4: ESG Topic | D4: Impact Score | E4: Impact Materiality | F4: Financial Score | G4: Financial Materiality | H4: DMA Classification | J4: 3 | K4: 1 | M4: 1 | N4: 3
A5: E01 | B5: =INDEX('Impact Scoring'!$B:$B,MATCH($A5,'Impact Scoring'!$A:$A,0)) -> Environmental | C5: =INDEX('Impact Scoring'!$C:$C,MATCH($A5,'Impact Scoring'!$A:$A,0)) -> Climate Change | D5: =INDEX('Impact Scoring'!$J:$J,MATCH($A5,'Impact Scoring'!$A:$A,0)) -> 5 | E5: =INDEX('Impact Scoring'!$K:$K,MATCH($A5,'Impact Scoring'!$A:$A,0)) -> Very High | F5: =INDEX('Financial Scoring'!$F:$F,MATCH($A5,'Financial Scoring'!$A:$A,0)) -> 5 | G5: =INDEX('Financial Scoring'!$G:$G,MATCH($A5,'Financial Scoring'!$A:$A,0)) -> Very High | H5: =IF(AND(D5>=3,F5>=3),"Double Material", IF(D5>=3,"Impact Material", IF(F5>=3,"Financially Material","Below Threshold"))) -> Double Material | J5: 3 | K5: 5 | M5: 5 | N5: 3
A6: E02 | B6: =INDEX('Impact Scoring'!$B:$B,MATCH($A6,'Impact Scoring'!$A:$A,0)) -> Environmental | C6: =INDEX('Impact Scoring'!$C:$C,MATCH($A6,'Impact Scoring'!$A:$A,0)) -> GHG Emissions | D6: =INDEX('Impact Scoring'!$J:$J,MATCH($A6,'Impact Scoring'!$A:$A,0)) -> 5 | E6: =INDEX('Impact Scoring'!$K:$K,MATCH($A6,'Impact Scoring'!$A:$A,0)) -> Very High | F6: =INDEX('Financial Scoring'!$F:$F,MATCH($A6,'Financial Scoring'!$A:$A,0)) -> 5 | G6: =INDEX('Financial Scoring'!$G:$G,MATCH($A6,'Financial Scoring'!$A:$A,0)) -> Very High | H6: =IF(AND(D6>=3,F6>=3),"Double Material", IF(D6>=3,"Impact Material", IF(F6>=3,"Financially Material","Below Threshold"))) -> Double Material
A7: E03 | B7: =INDEX('Impact Scoring'!$B:$B,MATCH($A7,'Impact Scoring'!$A:$A,0)) -> Environmental | C7: =INDEX('Impact Scoring'!$C:$C,MATCH($A7,'Impact Scoring'!$A:$A,0)) -> Energy Management | D7: =INDEX('Impact Scoring'!$J:$J,MATCH($A7,'Impact Scoring'!$A:$A,0)) -> 3.3333333 | E7: =INDEX('Impact Scoring'!$K:$K,MATCH($A7,'Impact Scoring'!$A:$A,0)) -> High | F7: =INDEX('Financial Scoring'!$F:$F,MATCH($A7,'Financial Scoring'!$A:$A,0)) -> 4 | G7: =INDEX('Financial Scoring'!$G:$G,MATCH($A7,'Financial Scoring'!$A:$A,0)) -> Very High | H7: =IF(AND(D7>=3,F7>=3),"Double Material", IF(D7>=3,"Impact Material", IF(F7>=3,"Financially Material","Below Threshold"))) -> Double Material | J7: Classification | K7: Number of Topics | M7: DMA Classification
A8: E04 | B8: =INDEX('Impact Scoring'!$B:$B,MATCH($A8,'Impact Scoring'!$A:$A,0)) -> Environmental | C8: =INDEX('Impact Scoring'!$C:$C,MATCH($A8,'Impact Scoring'!$A:$A,0)) -> Air Pollution | D8: =INDEX('Impact Scoring'!$J:$J,MATCH($A8,'Impact Scoring'!$A:$A,0)) -> 4.1166667 | E8: =INDEX('Impact Scoring'!$K:$K,MATCH($A8,'Impact Scoring'!$A:$A,0)) -> Very High | F8: =INDEX('Financial Scoring'!$F:$F,MATCH($A8,'Financial Scoring'!$A:$A,0)) -> 3.8 | G8: =INDEX('Financial Scoring'!$G:$G,MATCH($A8,'Financial Scoring'!$A:$A,0)) -> High | H8: =IF(AND(D8>=3,F8>=3),"Double Material", IF(D8>=3,"Impact Material", IF(F8>=3,"Financially Material","Below Threshold"))) -> Double Material | J8: Double Material | K8: =COUNTIF(H5:H34,"Double Material") -> 22 | M8: Impact | N8: Financial | O8: Classification
A9: E05 | B9: =INDEX('Impact Scoring'!$B:$B,MATCH($A9,'Impact Scoring'!$A:$A,0)) -> Environmental | C9: =INDEX('Impact Scoring'!$C:$C,MATCH($A9,'Impact Scoring'!$A:$A,0)) -> Water & Effluent | D9: =INDEX('Impact Scoring'!$J:$J,MATCH($A9,'Impact Scoring'!$A:$A,0)) -> 3.8 | E9: =INDEX('Impact Scoring'!$K:$K,MATCH($A9,'Impact Scoring'!$A:$A,0)) -> High | F9: =INDEX('Financial Scoring'!$F:$F,MATCH($A9,'Financial Scoring'!$A:$A,0)) -> 3.8 | G9: =INDEX('Financial Scoring'!$G:$G,MATCH($A9,'Financial Scoring'!$A:$A,0)) -> High | H9: =IF(AND(D9>=3,F9>=3),"Double Material", IF(D9>=3,"Impact Material", IF(F9>=3,"Financially Material","Below Threshold"))) -> Double Material | J9: Impact Material | K9: =COUNTIF(H5:H34,"Impact Material") -> 7 | M9: ≥ 3.00 | N9: ≥ 3.00 | O9: Double Material
